
class DemoException1 
{
	public static void main(String[] args) 
	{
		try
		{
			int arr[]=new int[3];
			System.out.println(10/0);
			System.out.println(arr[10]);
		}
		catch (ArithmeticException e)
		{
			System.out.println("arithmetic exception is valid");
		}
		catch(ArrayIndexOutOfBoundsException a)
		{
		
		   System.out.println("array exception is valid");
		}
		catch(Exception obj)
		{
			System.out.println("finally handled");
		}
	}
}
